nohup: ignoring input
/home/AI_project/superimage/model/teleBot.py:20: DeprecationWarning: textsize is deprecated and will be removed in Pillow 10 (2023-07-01). Use textbbox or textlength instead.
  w,h = draw.textsize(text,self.font)
2024-02-25 15:52:31,335 (__init__.py:960 MainThread) ERROR - TeleBot: "Infinity polling exception: ('Connection aborted.', TimeoutError('The write operation timed out'))"
2024-02-25 15:52:31,337 (__init__.py:962 MainThread) ERROR - TeleBot: "Exception traceback:
Traceback (most recent call last):
  File "/root/anaconda3/envs/sdwebui/lib/python3.10/site-packages/urllib3/connectionpool.py", line 715, in urlopen
    httplib_response = self._make_request(
  File "/root/anaconda3/envs/sdwebui/lib/python3.10/site-packages/urllib3/connectionpool.py", line 416, in _make_request
    conn.request(method, url, **httplib_request_kw)
  File "/root/anaconda3/envs/sdwebui/lib/python3.10/site-packages/urllib3/connection.py", line 244, in request
    super(HTTPConnection, self).request(method, url, body=body, headers=headers)
  File "/root/anaconda3/envs/sdwebui/lib/python3.10/http/client.py", line 1283, in request
    self._send_request(method, url, body, headers, encode_chunked)
  File "/root/anaconda3/envs/sdwebui/lib/python3.10/http/client.py", line 1329, in _send_request
    self.endheaders(body, encode_chunked=encode_chunked)
  File "/root/anaconda3/envs/sdwebui/lib/python3.10/http/client.py", line 1278, in endheaders
    self._send_output(message_body, encode_chunked=encode_chunked)
  File "/root/anaconda3/envs/sdwebui/lib/python3.10/http/client.py", line 1077, in _send_output
    self.send(chunk)
  File "/root/anaconda3/envs/sdwebui/lib/python3.10/http/client.py", line 999, in send
    self.sock.sendall(data)
  File "/root/anaconda3/envs/sdwebui/lib/python3.10/ssl.py", line 1270, in sendall
    v = self.send(byte_view[count:])
  File "/root/anaconda3/envs/sdwebui/lib/python3.10/ssl.py", line 1239, in send
    return self._sslobj.write(data)
TimeoutError: The write operation timed out

During handling of the above exception, another exception occurred:

Traceback (most recent call last):
  File "/root/anaconda3/envs/sdwebui/lib/python3.10/site-packages/requests/adapters.py", line 486, in send
    resp = conn.urlopen(
  File "/root/anaconda3/envs/sdwebui/lib/python3.10/site-packages/urllib3/connectionpool.py", line 799, in urlopen
    retries = retries.increment(
  File "/root/anaconda3/envs/sdwebui/lib/python3.10/site-packages/urllib3/util/retry.py", line 550, in increment
    raise six.reraise(type(error), error, _stacktrace)
  File "/root/anaconda3/envs/sdwebui/lib/python3.10/site-packages/urllib3/packages/six.py", line 769, in reraise
    raise value.with_traceback(tb)
  File "/root/anaconda3/envs/sdwebui/lib/python3.10/site-packages/urllib3/connectionpool.py", line 715, in urlopen
    httplib_response = self._make_request(
  File "/root/anaconda3/envs/sdwebui/lib/python3.10/site-packages/urllib3/connectionpool.py", line 416, in _make_request
    conn.request(method, url, **httplib_request_kw)
  File "/root/anaconda3/envs/sdwebui/lib/python3.10/site-packages/urllib3/connection.py", line 244, in request
    super(HTTPConnection, self).request(method, url, body=body, headers=headers)
  File "/root/anaconda3/envs/sdwebui/lib/python3.10/http/client.py", line 1283, in request
    self._send_request(method, url, body, headers, encode_chunked)
  File "/root/anaconda3/envs/sdwebui/lib/python3.10/http/client.py", line 1329, in _send_request
    self.endheaders(body, encode_chunked=encode_chunked)
  File "/root/anaconda3/envs/sdwebui/lib/python3.10/http/client.py", line 1278, in endheaders
    self._send_output(message_body, encode_chunked=encode_chunked)
  File "/root/anaconda3/envs/sdwebui/lib/python3.10/http/client.py", line 1077, in _send_output
    self.send(chunk)
  File "/root/anaconda3/envs/sdwebui/lib/python3.10/http/client.py", line 999, in send
    self.sock.sendall(data)
  File "/root/anaconda3/envs/sdwebui/lib/python3.10/ssl.py", line 1270, in sendall
    v = self.send(byte_view[count:])
  File "/root/anaconda3/envs/sdwebui/lib/python3.10/ssl.py", line 1239, in send
    return self._sslobj.write(data)
urllib3.exceptions.ProtocolError: ('Connection aborted.', TimeoutError('The write operation timed out'))

During handling of the above exception, another exception occurred:

Traceback (most recent call last):
  File "/root/anaconda3/envs/sdwebui/lib/python3.10/site-packages/telebot/__init__.py", line 955, in infinity_polling
    self.polling(non_stop=True, timeout=timeout, long_polling_timeout=long_polling_timeout,
  File "/root/anaconda3/envs/sdwebui/lib/python3.10/site-packages/telebot/__init__.py", line 1043, in polling
    self.__threaded_polling(non_stop=non_stop, interval=interval, timeout=timeout, long_polling_timeout=long_polling_timeout,
  File "/root/anaconda3/envs/sdwebui/lib/python3.10/site-packages/telebot/__init__.py", line 1118, in __threaded_polling
    raise e
  File "/root/anaconda3/envs/sdwebui/lib/python3.10/site-packages/telebot/__init__.py", line 1074, in __threaded_polling
    self.worker_pool.raise_exceptions()
  File "/root/anaconda3/envs/sdwebui/lib/python3.10/site-packages/telebot/util.py", line 147, in raise_exceptions
    raise self.exception_info
  File "/root/anaconda3/envs/sdwebui/lib/python3.10/site-packages/telebot/util.py", line 90, in run
    task(*args, **kwargs)
  File "/root/anaconda3/envs/sdwebui/lib/python3.10/site-packages/telebot/__init__.py", line 6801, in _run_middlewares_and_handler
    result = handler['function'](message)
  File "/home/AI_project/superimage/model/teleBot.py", line 66, in echo_all
    bot.send_photo(chat_id, photo=open(imPath, 'rb'))
  File "/root/anaconda3/envs/sdwebui/lib/python3.10/site-packages/telebot/__init__.py", line 1825, in send_photo
    apihelper.send_photo(
  File "/root/anaconda3/envs/sdwebui/lib/python3.10/site-packages/telebot/apihelper.py", line 494, in send_photo
    return _make_request(token, method_url, params=payload, files=files, method='post')
  File "/root/anaconda3/envs/sdwebui/lib/python3.10/site-packages/telebot/apihelper.py", line 156, in _make_request
    result = _get_req_session().request(
  File "/root/anaconda3/envs/sdwebui/lib/python3.10/site-packages/requests/sessions.py", line 589, in request
    resp = self.send(prep, **send_kwargs)
  File "/root/anaconda3/envs/sdwebui/lib/python3.10/site-packages/requests/sessions.py", line 703, in send
    r = adapter.send(request, **kwargs)
  File "/root/anaconda3/envs/sdwebui/lib/python3.10/site-packages/requests/adapters.py", line 501, in send
    raise ConnectionError(err, request=request)
requests.exceptions.ConnectionError: ('Connection aborted.', TimeoutError('The write operation timed out'))
"
