nohup: ignoring input
Error while getting Updates: Bad Gateway
No error handlers are registered, logging exception.
Traceback (most recent call last):
  File "/root/anaconda3/envs/sdwebui/lib/python3.10/site-packages/telegram/ext/_updater.py", line 742, in _network_loop_retry
    if not await do_action():
  File "/root/anaconda3/envs/sdwebui/lib/python3.10/site-packages/telegram/ext/_updater.py", line 736, in do_action
    return action_cb_task.result()
  File "/root/anaconda3/envs/sdwebui/lib/python3.10/site-packages/telegram/ext/_updater.py", line 387, in polling_action_cb
    raise exc
  File "/root/anaconda3/envs/sdwebui/lib/python3.10/site-packages/telegram/ext/_updater.py", line 376, in polling_action_cb
    updates = await self.bot.get_updates(
  File "/root/anaconda3/envs/sdwebui/lib/python3.10/site-packages/telegram/ext/_extbot.py", line 618, in get_updates
    updates = await super().get_updates(
  File "/root/anaconda3/envs/sdwebui/lib/python3.10/site-packages/telegram/_bot.py", line 541, in decorator
    result = await func(self, *args, **kwargs)
  File "/root/anaconda3/envs/sdwebui/lib/python3.10/site-packages/telegram/_bot.py", line 4177, in get_updates
    await self._post(
  File "/root/anaconda3/envs/sdwebui/lib/python3.10/site-packages/telegram/_bot.py", line 629, in _post
    return await self._do_post(
  File "/root/anaconda3/envs/sdwebui/lib/python3.10/site-packages/telegram/ext/_extbot.py", line 347, in _do_post
    return await super()._do_post(
  File "/root/anaconda3/envs/sdwebui/lib/python3.10/site-packages/telegram/_bot.py", line 657, in _do_post
    return await request.post(
  File "/root/anaconda3/envs/sdwebui/lib/python3.10/site-packages/telegram/request/_baserequest.py", line 200, in post
    result = await self._request_wrapper(
  File "/root/anaconda3/envs/sdwebui/lib/python3.10/site-packages/telegram/request/_baserequest.py", line 383, in _request_wrapper
    raise NetworkError(description or "Bad Gateway")
telegram.error.NetworkError: Bad Gateway
Error while getting Updates: Bad Gateway
No error handlers are registered, logging exception.
Traceback (most recent call last):
  File "/root/anaconda3/envs/sdwebui/lib/python3.10/site-packages/telegram/ext/_updater.py", line 742, in _network_loop_retry
    if not await do_action():
  File "/root/anaconda3/envs/sdwebui/lib/python3.10/site-packages/telegram/ext/_updater.py", line 736, in do_action
    return action_cb_task.result()
  File "/root/anaconda3/envs/sdwebui/lib/python3.10/site-packages/telegram/ext/_updater.py", line 387, in polling_action_cb
    raise exc
  File "/root/anaconda3/envs/sdwebui/lib/python3.10/site-packages/telegram/ext/_updater.py", line 376, in polling_action_cb
    updates = await self.bot.get_updates(
  File "/root/anaconda3/envs/sdwebui/lib/python3.10/site-packages/telegram/ext/_extbot.py", line 618, in get_updates
    updates = await super().get_updates(
  File "/root/anaconda3/envs/sdwebui/lib/python3.10/site-packages/telegram/_bot.py", line 541, in decorator
    result = await func(self, *args, **kwargs)
  File "/root/anaconda3/envs/sdwebui/lib/python3.10/site-packages/telegram/_bot.py", line 4177, in get_updates
    await self._post(
  File "/root/anaconda3/envs/sdwebui/lib/python3.10/site-packages/telegram/_bot.py", line 629, in _post
    return await self._do_post(
  File "/root/anaconda3/envs/sdwebui/lib/python3.10/site-packages/telegram/ext/_extbot.py", line 347, in _do_post
    return await super()._do_post(
  File "/root/anaconda3/envs/sdwebui/lib/python3.10/site-packages/telegram/_bot.py", line 657, in _do_post
    return await request.post(
  File "/root/anaconda3/envs/sdwebui/lib/python3.10/site-packages/telegram/request/_baserequest.py", line 200, in post
    result = await self._request_wrapper(
  File "/root/anaconda3/envs/sdwebui/lib/python3.10/site-packages/telegram/request/_baserequest.py", line 383, in _request_wrapper
    raise NetworkError(description or "Bad Gateway")
telegram.error.NetworkError: Bad Gateway
